Workbook

Sheet Labor Export P&L
A1: VIEC VUI COMPANY
A2: P&L Forecast
D3: Currency | E3: USD
D4: Rate: USD/VND | E4: 26500
D5: Rate: AUD/VND | E5: 19000
A6: Revenue Categories | B6: Quantity | C6: Per Unit | D6: Annual Total | E6: Annual Total VND
A7: Nurse Training Fees (65 Students) | B7: 74 | C7: 4000 | D7: =B7*C7 -> 296000 | E7: =D7*$E4 -> 7844000000 | F7: 8 thang dau chua co doanh thu, 4 thang sau 6 bạn 1 tháng (when start?), năm sau sẽ là 65 bạn
A8: Placement Commissions (65 Placements) | B8: 74 | C8: =(5000*19000)/26500 -> 3584.9057 | D8: =B8*C8 -> 265283.02 | E8: =D8*$E4 -> 7030000000 | F8: sẽ tính dòng tiền theo thời gian học, có thể họ sẽ ứng cho mình 40% cho 100 người khi ký hợp đồng, visa 3.5 cộng thời gian học 3.5 tháng. Khi ký được 40%, 7 tháng sau thì được hoa hồng
A9: Service package fee (excluding visa fee) | B9: 74 | C9: =2000 -> 2000 | D9: =B9*C9 -> 148000 | E9: =D9*$E4 -> 3922000000
A10: English + ielts 5.5_PTE 42 (including test fee) | B10: 74 | C10: =700 -> 700 | D10: =B10*C10 -> 51800 | E10: =D10*$E4 -> 1372700000
A11: Value Added Tax of Placement Commissions 10% | B11: 74 | C11: =C8*10% -> 358.49057 | D11: =B11*C11 -> 26528.302 | E11: =D11*$E4 -> 703000000 | F11: Vietnam | G11: từ 2027 sẽ có doanh thu
A12: Total Revenue | D12: =SUM(D7:D11) -> 787611.32 | E12: =SUM(E7:E11) -> 20871700000 | F12: Thi truong tang 20% moi nam
A14: Direct Costs (COGS)
A15: Australian RTO Licensing/Accreditation | B15: 74 | C15: =C7-((2500*19000)/26500) -> 2207.5472 | D15: =B15*C15 -> 163358.49 | E15: =D15*E4 -> 4329000000 | F15: Each student shall pay 2,500 AUD to the partner
A16: Lead Trainer Assessment (AU Qualified) | B16: 0 | C16: 0 | D16: 0 | E16: =D16*E4 -> 0
A17: English course IELTS 5.5/PTE 42 package (including test fee) shall be paid to 8A | B17: 74 | C17: 500 | D17: =B17*C17 -> 37000 | E17: =D17*E4 -> 980500000
A18: Local Vietnamese Clinical Support Staff | B18: 0 | C18: 0 | D18: 0 | E18: =D18*E4 -> 0
A19: Training Materials & Simulation Lab Ops | B19: 0 | C19: 0 | D19: 0 | E19: =D19*E4 -> 0
A20: Nursing Home Placements | B20: 74 | C20: 0 | D20: 0 | E20: =D20*E4 -> 0
A21: Total COGS | D21: =sum(D15:D20) -> 200358.49 | E21: =D21*E4 -> 5309500000
A22: Gross Profit | D22: =D12-D15 -> 624252.83 | E22: =E12-E15 -> 16542700000
A24: Operating Expenses (OPEX)
A25: CEO | B25: 1 | C25: 120000 | D25: 120000 | E25: =D25*E4 -> 3180000000 | F25: Gross + 1 satff năm 2
A26: Marketing & Student Sourcing (VN)_Phong | B26: 1 | C26: =35000000*13/26500 -> 17169.811 | D26: =B26*C26 -> 17169.811 | E26: =D26*E4 -> 455000000
A27: AU Business Development (Ben Van Leirop?) | B27: 0 | C27: 0 | D27: 0 | E27: =D27*E4 -> 0
A28: Rent & Utilities (HCMC/Hanoi Facility) | B28: 1 | C28: =1000*12 -> 12000 | D28: =B28*C28 -> 12000 | E28: =D28*E4 -> 318000000
A29: Legal & Migration Compliance Fees | B29: 1 | C29: =10000000*12/26500 -> 4528.3019 | D29: =B29*C29 -> 4528.3019 | E29: =D29*E4 -> 120000000 | F29: ser
A30: Support Staff | B30: 1 | C30: =10000000*13/26500 -> 4905.6604 | D30: =B30*C30 -> 4905.6604 | E30: =D30*E4 -> 130000000 | F30: Gross, 8 tháng năm đầu thưởng 1 thang
A31: Admin_Phương | B31: 1 | C31: =40000000*13/26500 -> 19622.642 | D31: =B31*C31 -> 19622.642 | E31: =D31*E4 -> 520000000 | F31: Gross + staff năm
A32: Other fee + event | B32: 1 | C32: =1000*12 -> 12000 | D32: =B32*C32 -> 12000 | E32: =D32*E4 -> 318000000 | F32: 1000 USD/tháng | G32: Tính thêm dự phòng 50tr/năm, chi phí dịch thuật, công chứng hồ sơ cho học viên. Khoảng 3tr/bộ
A33: Total OPEX | D33: =sum(D25:D32) -> 190226.42 | E33: =SUM(E25:E32) -> 5041000000
A35: EBITDA | D35: =D22-D33 -> 434026.42 | E35: =E22-E33 -> 11501700000
A36: Interest Expense | D36: 0 | E36: =D36*E4 -> 0
A37: Earnings Before Taxes | D37: =D35-D36 -> 434026.42 | E37: =E35-E36 -> 11501700000
A38: Income Taxes (CIT 20%) | D38: =D37*20% -> 86805.283 | E38: =E37*20% -> 2300340000
A39: Net Earnings | D39: =D37-D38 -> 347221.13 | E39: =E37-E38 -> 9201360000
E40: =E33/12 -> 4.2008333e+08 | F40: mỗi tháng + công chi phi thi truong
E41: =E40*8 -> 3360666667
E42: =E41/E4 -> 126817.61 | F42: Co the ngay tu dau phai co 3.5 tỷ
F44: Tháng 5 2026 bắt đầu - 2026 sẽ lỗ 8 tháng, và cần tính lỗ lũy kế

Sheet P&L 2026 - 2029
A1: VIEC VUI COMPANY
A2: P&L Forecast
A3: (2026 - Dec 2029)
D4: Currency | E4: USD
D5: Rate: USD/VND | E5: 26500
D6: Rate: AUD/VND | E6: 19000
A8: Categories | B8: 2026 | C8: 2027 | D8: 2028 | E8: 2029
A9: General Information
A10: Number of students | B10: 0 | C10: 72 | D10: =C10+C10*C11 -> 86.4 | E10: =D10+D10*D11 -> 103.68
A11: Estimated annual student growth rate | B11: 0 | C11: 0.2 | D11: 0.2 | E11: 0.2
A12: The placement commission earned per student is 5,000 AUD | B12: 5000 | C12: 5000 | D12: 5000 | E12: 5000
A13: CEO | B13: 1 | C13: 1 | D13: 1 | E13: 1
A14: Marketing & Student Sourcing | B14: 1 | C14: 1 | D14: 1 | E14: 1
A15: Admin | B15: 1 | C15: 1 | D15: 1 | E15: 1
A16: Support Staff | B16: 0 | C16: 0 | D16: 1 | E16: 1
A17: 2026: No salary increase or bonus, 2027: +1 month bonus; 2028 onwards : +1 month bonus +10% base salary increasent | B17: 0 | C17: 0 | D17: 0.1 | E17: 0.1
A18: Each student shall pay 2,500 AUD to the partner | B18: 2500 | C18: 2500 | D18: 2500 | E18: 2500
A20: Revenue
A21: Nurse Training Fees | B21: ='P&L 2026'!D21 -> 0 | C21: =' P&L 2027'!D21 -> 288000 | D21: ='P&L 2028'!D21 -> 345600 | E21: ='P&L 2029'!D21 -> 414720
A22: Placement Commissions | B22: ='P&L 2026'!D22 -> 0 | C22: =' P&L 2027'!D22 -> 258113.21 | D22: ='P&L 2028'!D22 -> 309735.85 | E22: ='P&L 2029'!D22 -> 371683.02
A23: Service package fee (excluding visa fee) | B23: ='P&L 2026'!D23 -> 0 | C23: =' P&L 2027'!D23 -> 144000 | D23: ='P&L 2028'!D23 -> 172800 | E23: ='P&L 2029'!D23 -> 207360
A24: English fee + ielts 5.5_PTE 42 (including test fee) | B24: ='P&L 2026'!D24 -> 0 | C24: =' P&L 2027'!D24 -> 50400 | D24: ='P&L 2028'!D24 -> 60480 | E24: ='P&L 2029'!D24 -> 72576
A25: Total Revenue | B25: ='P&L 2026'!D25 -> 0 | C25: =' P&L 2027'!D25 -> 740513.21 | D25: ='P&L 2028'!D25 -> 888615.85 | E25: ='P&L 2029'!D25 -> 1066339
B26: ='P&L 2026'!D26 | C26: =' P&L 2027'!D26 | D26: ='P&L 2028'!D26 | E26: ='P&L 2029'!D26
A27: Direct Costs (COGS) | B27: ='P&L 2026'!D27 | C27: =' P&L 2027'!D27 | D27: ='P&L 2028'!D27 | E27: ='P&L 2029'!D27
A28: Value Added Tax of Placement Commissions 10% | B28: ='P&L 2026'!D28 -> 0 | C28: =' P&L 2027'!D28 -> 25811.321 | D28: ='P&L 2028'!D28 -> 30973.585 | E28: ='P&L 2029'!D28 -> 37168.302
A29: Australian RTO Licensing/Accreditation | B29: ='P&L 2026'!D29 -> 0 | C29: =' P&L 2027'!D29 -> 158943.4 | D29: ='P&L 2028'!D29 -> 190732.08 | E29: ='P&L 2029'!D29 -> 228878.49
A30: Lead Trainer Assessment (AU Qualified) | B30: ='P&L 2026'!D30 -> 0 | C30: =' P&L 2027'!D30 -> 0 | D30: ='P&L 2028'!D30 -> 0 | E30: ='P&L 2029'!D30 -> 0
A31: English course IELTS 5.5/PTE 42 package (including test fee) shall be paid to 8A | B31: ='P&L 2026'!D31 -> 0 | C31: =' P&L 2027'!D31 -> 36000 | D31: ='P&L 2028'!D31 -> 43200 | E31: ='P&L 2029'!D31 -> 51840
A32: Local Vietnamese Clinical Support Staff | B32: ='P&L 2026'!D32 -> 0 | C32: =' P&L 2027'!D32 -> 0 | D32: ='P&L 2028'!D32 -> 0 | E32: ='P&L 2029'!D32 -> 0
A33: Training Materials & Simulation Lab Ops | B33: ='P&L 2026'!D33 -> 0 | C33: =' P&L 2027'!D33 -> 0 | D33: ='P&L 2028'!D33 -> 0 | E33: ='P&L 2029'!D33 -> 0
A34: Document Translation & Notarization Fee | B34: ='P&L 2026'!D34 -> 0 | C34: =' P&L 2027'!D34 -> 5760 | D34: ='P&L 2028'!D34 -> 6912 | E34: ='P&L 2029'!D34 -> 8294.4
A35: Nursing Home Placements | B35: ='P&L 2026'!D35 -> 0 | C35: =' P&L 2027'!D35 -> 0 | D35: ='P&L 2028'!D35 -> 0 | E35: ='P&L 2029'!D35 -> 0 | F35: waiting information from Ms. Hong
A36: Total COGS | B36: ='P&L 2026'!D36 -> 0 | C36: =' P&L 2027'!D36 -> 226514.72 | D36: ='P&L 2028'!D36 -> 271817.66 | E36: ='P&L 2029'!D36 -> 326181.19
A37: Gross Profit | B37: ='P&L 2026'!D37 -> 0 | C37: =' P&L 2027'!D37 -> 513998.49 | D37: ='P&L 2028'!D37 -> 616798.19 | E37: ='P&L 2029'!D37 -> 740157.83
B38: ='P&L 2026'!D38 | C38: =' P&L 2027'!D38 | D38: ='P&L 2028'!D38 | E38: ='P&L 2029'!D38
A39: Operating Expenses (OPEX) | B39: ='P&L 2026'!D39 | C39: =' P&L 2027'!D39 | D39: ='P&L 2028'!D39 | E39: ='P&L 2029'!D39
A40: CEO | B40: ='P&L 2026'!D40 -> 80000 | C40: =' P&L 2027'!D40 -> 120000 | D40: ='P&L 2028'!D40 -> 120000 | E40: ='P&L 2029'!D40 -> 120000
A41: Marketing & Student Sourcing (VN)_Phong | B41: ='P&L 2026'!D41 -> 10566.038 | C41: =' P&L 2027'!D41 -> 17169.811 | D41: ='P&L 2028'!D41 -> 18886.792 | E41: ='P&L 2029'!D41 -> 20775.472
A42: AU Business Development (Ben Van Leirop?) | B42: ='P&L 2026'!D42 -> 0 | C42: =' P&L 2027'!D42 -> 0 | D42: ='P&L 2028'!D42 -> 0 | E42: ='P&L 2029'!D42 -> 0
...

Sheet P&L 2026
A1: VIEC VUI COMPANY
A2: P&L Forecast
A3: (May 2026 - Dec 2026)
C4: Currency | D4: USD
C5: Rate: USD/VND | D5: 26500
C6: Rate: AUD/VND | D6: 19000
A8: Revenue Categories | B8: Information/Quantity | C8: Per Unit | D8: Annual Total
A9: General Information
A10: Number of students_2026 | B10: 0
A11: Estimated annual student growth rate | B11: 0.2
A12: The placement commission earned per student is 5,000 AUD | B12: 5000
A13: CEO | B13: 1
A14: Marketing & Student Sourcing | B14: 1
A15: Admin | B15: 1
A16: Support Staff | B16: 0
A17: 2026: No salary increase or bonus, 2027: +1 month bonus; 2028 onwards : +1 month bonus +10% base salary increasent | B17: 0.1
A18: Each student shall pay 2,500 AUD to the partner | B18: 2500
A20: Revenue
A21: Nurse Training Fees | B21: 0 | C21: 4000 | D21: =B21*C21 -> 0
A22: Placement Commissions | B22: 0 | C22: =(B12*D6)/D5 -> 3584.9057 | D22: =B22*C22 -> 0
A23: Service package fee (excluding visa fee) | B23: 0 | C23: =2000 -> 2000 | D23: =B23*C23 -> 0
A24: English fee + ielts 5.5_PTE 42 (including test fee) | B24: 0 | C24: =700 -> 700 | D24: =B24*C24 -> 0
A25: Total Revenue | D25: =SUM(D21:D24) -> 0
A27: Direct Costs (COGS)
A28: Value Added Tax of Placement Commissions 10% | B28: 0 | C28: =C22*10% -> 358.49057 | D28: =B28*C28 -> 0
A29: Australian RTO Licensing/Accreditation | B29: 0 | C29: =(C21-(B18*D6)/D5) -> 2207.5472 | D29: =B29*C29 -> 0
A30: Lead Trainer Assessment (AU Qualified) | B30: 0 | C30: 0 | D30: 0
A31: English course IELTS 5.5/PTE 42 package (including test fee) shall be paid to 8A | B31: 0 | C31: 500 | D31: =B31*C31 -> 0
A32: Local Vietnamese Clinical Support Staff | B32: 0 | C32: 0 | D32: 0
A33: Training Materials & Simulation Lab Ops | B33: 0 | C33: 0 | D33: 0
A34: Document Translation & Notarization Fee | B34: 0 | C34: 80 | D34: =B34*C34 -> 0
A35: Nursing Home Placements | B35: 0 | C35: 0 | D35: 0 | E35: waiting information from Ms. Hong
A36: Total COGS | D36: =sum(D29:D35) -> 0
A37: Gross Profit | D37: =D25-D29 -> 0
A39: Operating Expenses (OPEX)
A40: CEO | B40: 1 | C40: =10000*8 -> 80000 | D40: =B40*C40 -> 80000
A41: Marketing & Student Sourcing (VN)_Phong | B41: 1 | C41: =35000000*8/D5 -> 10566.038 | D41: =B41*C41 -> 10566.038
A42: AU Business Development (Ben Van Leirop?) | B42: 0 | C42: 0 | D42: 0
A43: Rent & Utilities (HCMC/Hanoi Facility) | B43: 1 | C43: =1000*8 -> 8000 | D43: =B43*C43 -> 8000
A44: Legal & Migration Compliance Fees | B44: 1 | C44: =5000000*8/D5 -> 1509.434 | D44: =B44*C44 -> 1509.434
...

Sheet  P&L 2027
A1: VIEC VUI COMPANY
A2: P&L Forecast
A3: ( Jan 2027 - Dec 2027)
C4: Currency | D4: USD
C5: Rate: USD/VND | D5: 26500
C6: Rate: AUD/VND | D6: 19000
A8: Revenue Categories | B8: Information/Quantity | C8: Per Unit | D8: Annual Total
A9: General Information
A10: Number of students_2027 | B10: =6*12 -> 72
A11: Estimated annual student growth rate | B11: 0.2
A12: The placement commission earned per student is 5,000 AUD | B12: 5000
A13: CEO | B13: 1
A14: Marketing & Student Sourcing | B14: 1
A15: Admin | B15: 1
A16: Support Staff | B16: 0
A17: 2026: No salary increase or bonus, 2027: +1 month bonus; 2028 onwards : +1 month bonus +10% base salary increasent | B17: 0.1
A18: Each student shall pay 2,500 AUD to the partner | B18: 2500
A20: Revenue
A21: Nurse Training Fees | B21: =B10 -> 72 | C21: 4000 | D21: =B21*C21 -> 288000
A22: Placement Commissions | B22: =B10 -> 72 | C22: =(B12*D6)/D5 -> 3584.9057 | D22: =B22*C22 -> 258113.21
A23: Service package fee (excluding visa fee) | B23: =B10 -> 72 | C23: =2000 -> 2000 | D23: =B23*C23 -> 144000
A24: English fee + ielts 5.5_PTE 42 (including test fee) | B24: =B10 -> 72 | C24: =700 -> 700 | D24: =B24*C24 -> 50400
A25: Total Revenue | D25: =SUM(D21:D24) -> 740513.21
A27: Direct Costs (COGS)
A28: Value Added Tax of Placement Commissions 10% | B28: =B10 -> 72 | C28: =C22*10% -> 358.49057 | D28: =B28*C28 -> 25811.321
A29: Australian RTO Licensing/Accreditation | B29: =B10 -> 72 | C29: =(C21-(B18*D6)/D5) -> 2207.5472 | D29: =B29*C29 -> 158943.4
A30: Lead Trainer Assessment (AU Qualified) | B30: 0 | C30: 0 | D30: 0
A31: English course IELTS 5.5/PTE 42 package (including test fee) shall be paid to 8A | B31: =B10 -> 72 | C31: 500 | D31: =B31*C31 -> 36000
A32: Local Vietnamese Clinical Support Staff | B32: 0 | C32: 0 | D32: 0
A33: Training Materials & Simulation Lab Ops | B33: 0 | C33: 0 | D33: 0
A34: Document Translation & Notarization Fee | B34: 72 | C34: 80 | D34: =B34*C34 -> 5760
A35: Nursing Home Placements | B35: 0 | C35: 0 | D35: 0 | E35: waiting information from Ms. Hong
A36: Total COGS | D36: =sum(D28:D35) -> 226514.72
A37: Gross Profit | D37: =D25-D36 -> 513998.49
A39: Operating Expenses (OPEX)
A40: CEO | B40: 1 | C40: =10000*12 -> 120000 | D40: =B40*C40 -> 120000
A41: Marketing & Student Sourcing (VN)_Phong | B41: 1 | C41: =35000000*13/D5 -> 17169.811 | D41: =B41*C41 -> 17169.811
A42: AU Business Development (Ben Van Leirop?) | B42: 0 | C42: 0 | D42: 0
A43: Rent & Utilities (HCMC/Hanoi Facility) | B43: 1 | C43: =1000*12 -> 12000 | D43: =B43*C43 -> 12000
A44: Legal & Migration Compliance Fees | B44: 1 | C44: =10000000*12/D5 -> 4528.3019 | D44: =B44*C44 -> 4528.3019
...

Sheet P&L 2028
A1: VIEC VUI COMPANY
A2: P&L Forecast
A3: ( Jan 2028- Dec 2028)
C4: Currency | D4: USD
C5: Rate: USD/VND | D5: 26500
C6: Rate: AUD/VND | D6: 19000
A8: Revenue Categories | B8: Information/Quantity | C8: Per Unit | D8: Annual Total
A9: General Information
A10: Number of students_2027 | B10: =6*12 -> 72
A11: Estimated annual student growth rate | B11: 0.2
A12: The placement commission earned per student is 5,000 AUD | B12: 5000
A13: CEO | B13: 1
A14: Marketing & Student Sourcing | B14: 1
A15: Admin | B15: 1
A16: Support Staff | B16: 1
A17: 2026: No salary increase or bonus, 2027: +1 month bonus; 2028 onwards : +1 month bonus +10% base salary increasent | B17: 0.1
A18: Each student shall pay 2,500 AUD to the partner | B18: 2500
A20: Revenue
A21: Nurse Training Fees | B21: =B10+B10*B11 -> 86.4 | C21: 4000 | D21: =B21*C21 -> 345600
A22: Placement Commissions | B22: =B21 -> 86.4 | C22: =(B12*D6)/D5 -> 3584.9057 | D22: =B22*C22 -> 309735.85
A23: Service package fee (excluding visa fee) | B23: =B21 -> 86.4 | C23: =2000 -> 2000 | D23: =B23*C23 -> 172800
A24: English fee + ielts 5.5_PTE 42 (including test fee) | B24: =B21 -> 86.4 | C24: =700 -> 700 | D24: =B24*C24 -> 60480
A25: Total Revenue | D25: =SUM(D21:D24) -> 888615.85
A27: Direct Costs (COGS)
A28: Value Added Tax of Placement Commissions 10% | B28: =B21 -> 86.4 | C28: =C22*10% -> 358.49057 | D28: =B28*C28 -> 30973.585
A29: Australian RTO Licensing/Accreditation | B29: =B21 -> 86.4 | C29: =(C21-(B18*D6)/D5) -> 2207.5472 | D29: =B29*C29 -> 190732.08
A30: Lead Trainer Assessment (AU Qualified) | B30: 0 | C30: 0 | D30: 0
A31: English course IELTS 5.5/PTE 42 package (including test fee) shall be paid to 8A | B31: =B21 -> 86.4 | C31: 500 | D31: =B31*C31 -> 43200
A32: Local Vietnamese Clinical Support Staff | B32: 0 | C32: 0 | D32: 0
A33: Training Materials & Simulation Lab Ops | B33: 0 | C33: 0 | D33: 0
A34: Document Translation & Notarization Fee | B34: =B21 -> 86.4 | C34: 80 | D34: =B34*C34 -> 6912
A35: Nursing Home Placements | B35: 0 | C35: 0 | D35: 0 | E35: waiting information from Ms. Hong
A36: Total COGS | D36: =sum(D28:D35) -> 271817.66
A37: Gross Profit | D37: =D25-D36 -> 616798.19
A39: Operating Expenses (OPEX)
A40: CEO | B40: 1 | C40: =10000*12 -> 120000 | D40: =B40*C40 -> 120000
A41: Marketing & Student Sourcing (VN)_Phong | B41: 1 | C41: =35000000*13/D5+35000000*13/D5*B17 -> 18886.792 | D41: =B41*C41 -> 18886.792
A42: AU Business Development (Ben Van Leirop?) | B42: 0 | C42: 0 | D42: 0
A43: Rent & Utilities (HCMC/Hanoi Facility) | B43: 1 | C43: =1000*12 -> 12000 | D43: =B43*C43 -> 12000
A44: Legal & Migration Compliance Fees | B44: 1 | C44: =10000000*12/D5 -> 4528.3019 | D44: =B44*C44 -> 4528.3019
...

Sheet P&L 2029
A1: VIEC VUI COMPANY
A2: P&L Forecast
A3: ( Jan 2029- Dec 2029)
C4: Currency | D4: USD
C5: Rate: USD/VND | D5: 26500
C6: Rate: AUD/VND | D6: 19000
A8: Revenue Categories | B8: Information/Quantity | C8: Per Unit | D8: Annual Total
A9: General Information
A10: Number of students_2028 | B10: ='P&L 2028'!B21 -> 86.4
A11: Estimated annual student growth rate | B11: 0.2
A12: The placement commission earned per student is 5,000 AUD | B12: 5000
A13: CEO | B13: 1
A14: Marketing & Student Sourcing | B14: 1
A15: Admin | B15: 1
A16: Support Staff | B16: 1
A17: 2026: No salary increase or bonus, 2027: +1 month bonus; 2028 onwards : +1 month bonus +10% base salary increasent | B17: 0.1
A18: Each student shall pay 2,500 AUD to the partner | B18: 2500
A20: Revenue
A21: Nurse Training Fees | B21: =B10+B10*B11 -> 103.68 | C21: 4000 | D21: =B21*C21 -> 414720
A22: Placement Commissions | B22: =B21 -> 103.68 | C22: =(B12*D6)/D5 -> 3584.9057 | D22: =B22*C22 -> 371683.02
A23: Service package fee (excluding visa fee) | B23: =B21 -> 103.68 | C23: =2000 -> 2000 | D23: =B23*C23 -> 207360
A24: English fee + ielts 5.5_PTE 42 (including test fee) | B24: =B21 -> 103.68 | C24: =700 -> 700 | D24: =B24*C24 -> 72576
A25: Total Revenue | D25: =SUM(D21:D24) -> 1066339
A27: Direct Costs (COGS)
A28: Value Added Tax of Placement Commissions 10% | B28: =B21 -> 103.68 | C28: =C22*10% -> 358.49057 | D28: =B28*C28 -> 37168.302
A29: Australian RTO Licensing/Accreditation | B29: =B21 -> 103.68 | C29: =(C21-(B18*D6)/D5) -> 2207.5472 | D29: =B29*C29 -> 228878.49
A30: Lead Trainer Assessment (AU Qualified) | B30: 0 | C30: 0 | D30: 0
A31: English course IELTS 5.5/PTE 42 package (including test fee) shall be paid to 8A | B31: =B21 -> 103.68 | C31: 500 | D31: =B31*C31 -> 51840
A32: Local Vietnamese Clinical Support Staff | B32: 0 | C32: 0 | D32: 0
A33: Training Materials & Simulation Lab Ops | B33: 0 | C33: 0 | D33: 0
A34: Document Translation & Notarization Fee | B34: =B21 -> 103.68 | C34: 80 | D34: =B34*C34 -> 8294.4
A35: Nursing Home Placements | B35: 0 | C35: 0 | D35: 0 | E35: waiting information from Ms. Hong
A36: Total COGS | D36: =sum(D28:D35) -> 326181.19
A37: Gross Profit | D37: =D25-D36 -> 740157.83
A39: Operating Expenses (OPEX)
A40: CEO | B40: 1 | C40: =10000*12 -> 120000 | D40: =B40*C40 -> 120000
A41: Marketing & Student Sourcing (VN)_Phong | B41: 1 | C41: ='P&L 2028'!D41+'P&L 2028'!D41*B17 -> 20775.472 | D41: =B41*C41 -> 20775.472
A42: AU Business Development (Ben Van Leirop?) | B42: 0 | C42: 0 | D42: 0
A43: Rent & Utilities (HCMC/Hanoi Facility) | B43: 1 | C43: =1000*12 -> 12000 | D43: =B43*C43 -> 12000
A44: Legal & Migration Compliance Fees | B44: 1 | C44: =10000000*12/D5 -> 4528.3019 | D44: =B44*C44 -> 4528.3019
...

Sheet P&L 2026 - Monthly Breakdown 
A1: VIEC VUI COMPANY
A2: P&L Forecast
A3: (May 2026 - Dec 2026)
L4: USD
L5: 26500
L6: 19000
A8: Revenue Categories | B8: Information/Quantity | C8: Per Unit | D8: May | E8: June | F8: July | G8: Augs | H8: Sep | I8: Oct | J8: Nov | K8: Dec | L8: Annual Total
A9: General Information
A10: Number of students_2026 | B10: 0
A11: Estimated annual student growth rate | B11: 0.2
A12: The placement commission earned per student is 5,000 AUD | B12: 5000
A13: CEO | B13: 1
A14: Marketing & Student Sourcing | B14: 1
A15: Admin | B15: 1
A16: Support Staff | B16: 0
A17: Employee salaries are projected to increase annually | B17: 0.1
A18: Each student shall pay 2,500 AUD to the partner | B18: 2500
A20: Revenue
A21: Nurse Training Fees | B21: 0 | C21: 4000 | D21: 0 | E21: 0 | F21: 0 | G21: 0 | H21: 0 | I21: 0 | J21: 0 | K21: 0 | L21: =SUM(D21:K21) -> 0
A22: Placement Commissions | B22: 0 | C22: =(B12*L6)/L5 -> 3584.9057 | D22: 0 | E22: 0 | F22: 0 | G22: 0 | H22: 0 | I22: 0 | J22: 0 | K22: 0 | L22: =SUM(D22:K22) -> 0
A23: Service package fee (excluding visa fee) | B23: 0 | C23: =2000 -> 2000 | D23: 0 | E23: 0 | F23: 0 | G23: 0 | H23: 0 | I23: 0 | J23: 0 | K23: 0 | L23: =SUM(D23:K23) -> 0
A24: English fee + ielts 5.5_PTE 42 (including test fee) | B24: 0 | C24: =700 -> 700 | D24: 0 | E24: 0 | F24: 0 | G24: 0 | H24: 0 | I24: 0 | J24: 0 | K24: 0 | L24: =SUM(D24:K24) -> 0
A25: Total Revenue | D25: =SUM(D21:D24) -> 0 | E25: =SUM(E21:E24) -> 0 | F25: =SUM(F21:F24) -> 0 | G25: =SUM(G21:G24) -> 0 | H25: =SUM(H21:H24) -> 0 | I25: =SUM(I21:I24) -> 0 | J25: =SUM(J21:J24) -> 0 | K25: =SUM(K21:K24) -> 0 | L25: =SUM(L21:L24) -> 0
A27: Direct Costs (COGS)
A28: Value Added Tax of Placement Commissions 10% | B28: 0 | C28: =C22*10% -> 358.49057 | D28: 0 | E28: 0 | F28: 0 | G28: 0 | H28: 0 | I28: 0 | J28: 0 | K28: 0 | L28: =SUM(D28:K28) -> 0
A29: Australian RTO Licensing/Accreditation | B29: 0 | C29: =(C21-(B18*L6)/L5) -> 2207.5472 | D29: 0 | E29: 0 | F29: 0 | G29: 0 | H29: 0 | I29: 0 | J29: 0 | K29: 0 | L29: =SUM(D29:K29) -> 0
A30: Lead Trainer Assessment (AU Qualified) | B30: 0 | C30: 0 | D30: 0 | E30: 0 | F30: 0 | G30: 0 | H30: 0 | I30: 0 | J30: 0 | K30: 0 | L30: =SUM(D30:K30) -> 0
A31: English course IELTS 5.5/PTE 42 package (including test fee) shall be paid to 8A | B31: 0 | C31: 500 | D31: 0 | E31: 0 | F31: 0 | G31: 0 | H31: 0 | I31: 0 | J31: 0 | K31: 0 | L31: =SUM(D31:K31) -> 0
A32: Local Vietnamese Clinical Support Staff | B32: 0 | C32: 0 | D32: 0 | E32: 0 | F32: 0 | G32: 0 | H32: 0 | I32: 0 | J32: 0 | K32: 0 | L32: =SUM(D32:K32) -> 0
A33: Training Materials & Simulation Lab Ops | B33: 0 | C33: 0 | D33: 0 | E33: 0 | F33: 0 | G33: 0 | H33: 0 | I33: 0 | J33: 0 | K33: 0 | L33: =SUM(D33:K33) -> 0
A34: Document Translation & Notarization Fee | B34: 0 | C34: 0 | D34: 0 | E34: 0 | F34: 0 | G34: 0 | H34: 0 | I34: 0 | J34: 0 | K34: 0 | L34: =SUM(D34:K34) -> 0
A35: Nursing Home Placements | B35: 0 | C35: 0 | D35: 0 | E35: 0 | F35: 0 | G35: 0 | H35: 0 | I35: 0 | J35: 0 | K35: 0 | L35: =SUM(D35:K35) -> 0 | M35: Awaiting information from Ms. Hong
A36: Total COGS | D36: =SUM(D28:D35) -> 0 | E36: =SUM(E28:E35) -> 0 | F36: =SUM(F28:F35) -> 0 | G36: =SUM(G28:G35) -> 0 | H36: =SUM(H28:H35) -> 0 | I36: =SUM(I28:I35) -> 0 | J36: =SUM(J28:J35) -> 0 | K36: =SUM(K28:K35) -> 0 | L36: =SUM(L28:L35) -> 0
A37: Gross Profit | D37: =D25-D36 -> 0 | E37: =E25-E36 -> 0 | F37: =F25-F36 -> 0 | G37: =G25-G36 -> 0 | H37: =H25-H36 -> 0 | I37: =I25-I36 -> 0 | J37: =J25-J36 -> 0 | K37: =K25-K36 -> 0 | L37: =L25-L36 -> 0
A39: Operating Expenses (OPEX)
A40: CEO | B40: 1 | C40: 10000 | D40: =C40 -> 10000 | E40: =D40 -> 10000 | F40: =E40 -> 10000 | G40: =F40 -> 10000 | H40: =G40 -> 10000 | I40: =H40 -> 10000 | J40: =I40 -> 10000 | K40: =J40 -> 10000 | L40: =SUM(D40:K40) -> 80000
A41: Marketing & Student Sourcing (VN)_Phong | B41: 1 | C41: =35000000/L5 -> 1320.7547 | D41: =C41 -> 1320.7547 | E41: =D41 -> 1320.7547 | F41: =E41 -> 1320.7547 | G41: =F41 -> 1320.7547 | H41: =G41 -> 1320.7547 | I41: =H41 -> 1320.7547 | J41: =I41 -> 1320.7547 | K41: =J41 -> 1320.7547 | L41: =SUM(D41:K41) -> 10566.038
A42: AU Business Development (Ben Van Leirop?) | B42: 0 | C42: 0 | D42: =C42 -> 0 | E42: =D42 -> 0 | F42: =E42 -> 0 | G42: =F42 -> 0 | H42: =G42 -> 0 | I42: =H42 -> 0 | J42: =I42 -> 0 | K42: =J42 -> 0 | L42: =SUM(D42:K42) -> 0
A43: Rent & Utilities (HCMC/Hanoi Facility) | B43: 1 | C43: =1000 -> 1000 | D43: =C43 -> 1000 | E43: =D43 -> 1000 | F43: =E43 -> 1000 | G43: =F43 -> 1000 | H43: =G43 -> 1000 | I43: =H43 -> 1000 | J43: =I43 -> 1000 | K43: =J43 -> 1000 | L43: =SUM(D43:K43) -> 8000
A44: Legal & Migration Compliance Fees | B44: 1 | C44: =5000000/L5 -> 188.67925 | D44: =C44 -> 188.67925 | E44: =D44 -> 188.67925 | F44: =E44 -> 188.67925 | G44: =F44 -> 188.67925 | H44: =G44 -> 188.67925 | I44: =H44 -> 188.67925 | J44: =I44 -> 188.67925 | K44: =J44 -> 188.67925 | L44: =SUM(D44:K44) -> 1509.434
...

Sheet P&L 2027 - Monthly Breakdown 
A1: VIEC VUI COMPANY
A2: P&L Forecast
A3: ( Jan 2027 - Dec 2027)
P4: USD
P5: 26500
P6: 19000
A8: Revenue Categories | B8: Information/Quantity | C8: Annual Total | D8: Jan | E8: Feb | F8: March | G8: April | H8: May | I8: June | J8: July | K8: Augs | L8: Sep | M8: Oct | N8: Nov | O8: Dec | P8: Annual Total | Q8: Check
A9: General Information
A10: Number of students_2026 | B10: 0
A11: Estimated 6 students per month from 2027
A12: Estimated annual student growth rate | B12: 0.2
A13: The placement commission earned per student is 5,000 AUD | B13: 5000
A14: CEO | B14: 1
A15: Marketing & Student Sourcing | B15: 1
A16: Admin | B16: 1
A17: Support Staff | B17: 0
A18: Employee salaries are projected to increase annually | B18: 0.1
A19: Each student shall pay 2,500 AUD to the partner | B19: 2500
A20: Upon contract signing at the beginning of the year, a 40% commission shall be paid. The remaining 60% will be received 7 months later, with the commission calculated accordingly based on this timeline
A21: Revenue
A22: Nurse Training Fees | B22: =' P&L 2027'!B21 -> 72 | C22: =' P&L 2027'!D21 -> 288000 | D22: =C22/12 -> 24000 | E22: =D22 -> 24000 | F22: =E22 -> 24000 | G22: =F22 -> 24000 | H22: =G22 -> 24000 | I22: =H22 -> 24000 | J22: =I22 -> 24000 | K22: =J22 -> 24000 | L22: =K22 -> 24000 | ... O22: =N22 -> 24000 | P22: =SUM(D22:O22) -> 288000 | Q22: =C22-P22 -> 0
A23: Placement Commissions | B23: =' P&L 2027'!B22 -> 72 | C23: =' P&L 2027'!D22 -> 258113.21 | D23: =C23*40% -> 103245.28 | E23: 0 | F23: 0 | G23: 0 | H23: 0 | I23: 0 | J23: =C23*60%/12 -> 12905.66 | K23: =C23*60%/12 -> 12905.66 | L23: =C23*60%/12 -> 12905.66 | M23: =C23*60%/12 -> 12905.66 | N23: =C23*60%/12 -> 12905.66 | O23: =C23*60%/12 -> 12905.66 | P23: =SUM(D23:O23) -> 180679.25 | Q23: =C23-P23 -> 77433.962 | R23: ok
A24: Service package fee (excluding visa fee) | B24: =' P&L 2027'!B23 -> 72 | C24: =' P&L 2027'!D23 -> 144000 | D24: =C24/12 -> 12000 | E24: =D24 -> 12000 | F24: =E24 -> 12000 | G24: =F24 -> 12000 | H24: =G24 -> 12000 | I24: =H24 -> 12000 | J24: =I24 -> 12000 | K24: =J24 -> 12000 | L24: =K24 -> 12000 | ... O24: =N24 -> 12000 | P24: =SUM(D24:O24) -> 144000 | Q24: =C24-P24 -> 0
A25: English fee + ielts 5.5_PTE 42 (including test fee) | B25: =' P&L 2027'!B24 -> 72 | C25: =' P&L 2027'!D24 -> 50400 | D25: =C25/12 -> 4200 | E25: =D25 -> 4200 | F25: =E25 -> 4200 | G25: =F25 -> 4200 | H25: =G25 -> 4200 | I25: =H25 -> 4200 | J25: =I25 -> 4200 | K25: =J25 -> 4200 | L25: =K25 -> 4200 | ... O25: =N25 -> 4200 | P25: =SUM(D25:O25) -> 50400 | Q25: =C25-P25 -> 0
A26: Total Revenue | B26: =' P&L 2027'!B25 | C26: =' P&L 2027'!D25 -> 740513.21 | D26: =SUM(D22:D25) -> 143445.28 | E26: =SUM(E22:E25) -> 40200 | F26: =SUM(F22:F25) -> 40200 | G26: =SUM(G22:G25) -> 40200 | H26: =SUM(H22:H25) -> 40200 | I26: =SUM(I22:I25) -> 40200 | J26: =SUM(J22:J25) -> 53105.66 | K26: =SUM(K22:K25) -> 53105.66 | ... P26: =SUM(P22:P25) -> 663079.25 | Q26: =C26-P26 -> 77433.962
B27: =' P&L 2027'!B26 | C27: =' P&L 2027'!D26 | Q27: =C27-P27 -> 0
A28: Direct Costs (COGS) | B28: =' P&L 2027'!B27 | C28: =' P&L 2027'!D27 | Q28: =C28-P28 -> 0
A29: Value Added Tax of Placement Commissions 10% | B29: =' P&L 2027'!B28 -> 72 | C29: =' P&L 2027'!D28 -> 25811.321 | D29: =D23*10% -> 10324.528 | E29: =E23*10% -> 0 | F29: =F23*10% -> 0 | G29: =G23*10% -> 0 | H29: =H23*10% -> 0 | I29: =I23*10% -> 0 | J29: =J23*10% -> 1290.566 | K29: =K23*10% -> 1290.566 | ... O29: =O23*10% -> 1290.566 | P29: =SUM(D29:O29) -> 18067.925 | Q29: =C29-P29 -> 7743.3962 | R29: VAT gối đầu 6 tháng
A30: Australian RTO Licensing/Accreditation | B30: =' P&L 2027'!B29 -> 72 | C30: =' P&L 2027'!D29 -> 158943.4 | D30: =C30/12 -> 13245.283 | E30: =D30 -> 13245.283 | F30: =E30 -> 13245.283 | G30: =F30 -> 13245.283 | H30: =G30 -> 13245.283 | I30: =H30 -> 13245.283 | J30: =I30 -> 13245.283 | K30: =J30 -> 13245.283 | L30: =K30 -> 13245.283 | ... O30: =N30 -> 13245.283 | P30: =SUM(D30:O30) -> 158943.4 | Q30: =C30-P30 -> 0
A31: Lead Trainer Assessment (AU Qualified) | B31: =' P&L 2027'!B30 -> 0 | C31: =' P&L 2027'!D30 -> 0 | D31: 0 | E31: 0 | F31: 0 | G31: 0 | H31: 0 | I31: 0 | J31: 0 | K31: 0 | L31: 0 | M31: 0 | N31: 0 | O31: 0 | P31: =SUM(D31:O31) -> 0 | Q31: =C31-P31 -> 0
A32: English course IELTS 5.5/PTE 42 package (including test fee) shall be paid to 8A | B32: =' P&L 2027'!B31 -> 72 | C32: =' P&L 2027'!D31 -> 36000 | D32: =C32/12 -> 3000 | E32: =D32 -> 3000 | F32: =E32 -> 3000 | G32: =F32 -> 3000 | H32: =G32 -> 3000 | I32: =H32 -> 3000 | J32: =I32 -> 3000 | K32: =J32 -> 3000 | L32: =K32 -> 3000 | ... O32: =N32 -> 3000 | P32: =SUM(D32:O32) -> 36000 | Q32: =C32-P32 -> 0
A33: Local Vietnamese Clinical Support Staff | B33: =' P&L 2027'!B32 -> 0 | C33: =' P&L 2027'!D32 -> 0 | D33: 0 | E33: 0 | F33: 0 | G33: 0 | H33: 0 | I33: 0 | J33: 0 | K33: 0 | L33: 0 | M33: 0 | N33: 0 | O33: 0 | P33: =SUM(D33:O33) -> 0 | Q33: =C33-P33 -> 0
A34: Training Materials & Simulation Lab Ops | B34: =' P&L 2027'!B33 -> 0 | C34: =' P&L 2027'!D33 -> 0 | D34: 0 | E34: 0 | F34: 0 | G34: 0 | H34: 0 | I34: 0 | J34: 0 | K34: 0 | L34: 0 | M34: 0 | N34: 0 | O34: 0 | P34: =SUM(D34:O34) -> 0 | Q34: =C34-P34 -> 0
A35: Document Translation & Notarization Fee | B35: =' P&L 2027'!B34 -> 72 | C35: =' P&L 2027'!D34 -> 5760 | D35: =C35/12 -> 480 | E35: =C35/12 -> 480 | F35: =D35 -> 480 | G35: =E35 -> 480 | H35: =F35 -> 480 | I35: =G35 -> 480 | J35: =H35 -> 480 | K35: =I35 -> 480 | L35: =J35 -> 480 | M35: =K35 -> 480 | ... O35: =M35 -> 480 | P35: =SUM(D35:O35) -> 5760 | Q35: =C35-P35 -> 0
A36: Nursing Home Placements | B36: =' P&L 2027'!B35 -> 0 | C36: =' P&L 2027'!D35 -> 0 | D36: 0 | E36: 0 | F36: 0 | G36: 0 | H36: 0 | I36: 0 | J36: 0 | K36: 0 | L36: 0 | M36: 0 | N36: 0 | O36: 0 | P36: =SUM(D36:O36) -> 0 | Q36: =C36-P36 -> 0
A37: Total COGS | B37: =' P&L 2027'!B35 -> 0 | C37: =' P&L 2027'!D36 -> 226514.72 | D37: =SUM(D29:D36) -> 27049.811 | E37: =SUM(E29:E36) -> 16725.283 | F37: =SUM(F29:F36) -> 16725.283 | G37: =SUM(G29:G36) -> 16725.283 | H37: =SUM(H29:H36) -> 16725.283 | I37: =SUM(I29:I36) -> 16725.283 | J37: =SUM(J29:J36) -> 18015.849 | K37: =SUM(K29:K36) -> 18015.849 | ... O37: =SUM(O29:O36) -> 18015.849 | P37: =SUM(D37:O37) -> 218771.32 | Q37: =C37-P37 -> 7743.3962
A38: Gross Profit | B38: =' P&L 2027'!B36 | C38: =' P&L 2027'!D37 -> 513998.49 | D38: =D26-D37 -> 116395.47 | E38: =E26-E37 -> 23474.717 | F38: =F26-F37 -> 23474.717 | G38: =G26-G37 -> 23474.717 | H38: =H26-H37 -> 23474.717 | I38: =I26-I37 -> 23474.717 | J38: =J26-J37 -> 35089.811 | K38: =K26-K37 -> 35089.811 | ... O38: =O26-O37 -> 35089.811 | P38: =SUM(D38:O38) -> 444307.92 | Q38: =C38-P38 -> 69690.566 | R38: =Q26-Q37 -> 69690.566 | S38: ok
B39: =' P&L 2027'!B37 | Q39: =C39-P39 -> 0
C40: =' P&L 2027'!D39
A41: Operating Expenses (OPEX) | B41: =' P&L 2027'!B38 | C41: =' P&L 2027'!D39 | Q41: =C41-P41 -> 0
...
